Workbook

Sheet Data
A1: product_image | B1: source | C1: product_id | D1: product_category | E1: product_description | F1: british_columbia | G1: manitoba | H1: ontario | I1: prince_edward_island | J1: quebec | K1: c1 | L1: c2 | M1: c3
B2: Product Guide | C2: =M2 -> 111111111111 | D2: Fluorescent tubes measuring less than or equal to 2 ft | E2: Includes all diameters and light outputs, shaped fluorescent tubes, and UV-A and UV-B tubes. | F2: 0.2 | G2: 1 | H2: C | I2: 0.4 | J2: 0.35 | K2: =_xlfn.CONCAT(LEFT(D2,100),LEFT(E2,100)) -> Fluorescent tubes measuring less than or equal to 2 ftIncludes all diameters and light outputs, shaped fluorescent tubes, and UV-A and UV-B tubes. | L2: =COUNTIF($K$2:K2,K2) -> 1 | M2: =_xlfn.IFNA(_xlfn.CONCAT(VLOOKUP(K2,'ID Generation'!J:K,2,FALSE),100+10*L2+1),"") -> 111111111111
B3: Product Guide | C3: =M3 -> 111111111121 | D3: Fluorescent tubes measuring less than or equal to 2 ft | E3: Includes all diameters and light outputs, shaped fluorescent tubes, and UV-A and UV-B tubes. | F3: 0.2 | G3: 1 | H3: C | I3: 0.4 | J3: 0.35 | K3: =_xlfn.CONCAT(LEFT(D3,100),LEFT(E3,100)) -> Fluorescent tubes measuring less than or equal to 2 ftIncludes all diameters and light outputs, shaped fluorescent tubes, and UV-A and UV-B tubes. | L3: =COUNTIF($K$2:K3,K3) -> 2 | M3: =_xlfn.IFNA(_xlfn.CONCAT(VLOOKUP(K3,'ID Generation'!J:K,2,FALSE),100+10*L3+1),"") -> 111111111121
B4: Product Guide | C4: =M4 -> 111111111131 | D4: Fluorescent tubes measuring less than or equal to 2 ft | E4: Includes all diameters and light outputs, shaped fluorescent tubes, and UV-A and UV-B tubes. | F4: 0.2 | G4: 1 | H4: C | I4: 0.4 | J4: 0.35 | K4: =_xlfn.CONCAT(LEFT(D4,100),LEFT(E4,100)) -> Fluorescent tubes measuring less than or equal to 2 ftIncludes all diameters and light outputs, shaped fluorescent tubes, and UV-A and UV-B tubes. | L4: =COUNTIF($K$2:K4,K4) -> 3 | M4: =_xlfn.IFNA(_xlfn.CONCAT(VLOOKUP(K4,'ID Generation'!J:K,2,FALSE),100+10*L4+1),"") -> 111111111131
B5: Product Guide | C5: =M5 -> 111111111141 | D5: Fluorescent tubes measuring less than or equal to 2 ft | E5: Includes all diameters and light outputs, shaped fluorescent tubes, and UV-A and UV-B tubes. | F5: 0.2 | G5: 1 | H5: C | I5: 0.4 | J5: 0.35 | K5: =_xlfn.CONCAT(LEFT(D5,100),LEFT(E5,100)) -> Fluorescent tubes measuring less than or equal to 2 ftIncludes all diameters and light outputs, shaped fluorescent tubes, and UV-A and UV-B tubes. | L5: =COUNTIF($K$2:K5,K5) -> 4 | M5: =_xlfn.IFNA(_xlfn.CONCAT(VLOOKUP(K5,'ID Generation'!J:K,2,FALSE),100+10*L5+1),"") -> 111111111141
B6: Product Guide | C6: =M6 -> 121111111111 | D6: Fluorescent tubes measuring greater than 2 ft and up to or equal to 4 ft | E6: Includes all diameters and light outputs, shaped fluorescent tubes, and UV-A and UV-B tubes. | F6: 0.4 | G6: 1.8 | H6: C | I6: 0.8 | J6: 0.65 | K6: =_xlfn.CONCAT(LEFT(D6,100),LEFT(E6,100)) -> Fluorescent tubes measuring greater than 2 ft and up to or equal to 4 ftIncludes all diameters and light outputs, shaped fluorescent tubes, and UV-A and UV-B tubes. | L6: =COUNTIF($K$2:K6,K6) -> 1 | M6: =_xlfn.IFNA(_xlfn.CONCAT(VLOOKUP(K6,'ID Generation'!J:K,2,FALSE),100+10*L6+1),"") -> 121111111111
B7: Product Guide | C7: =M7 -> 121111111121 | D7: Fluorescent tubes measuring greater than 2 ft and up to or equal to 4 ft | E7: Includes all diameters and light outputs, shaped fluorescent tubes, and UV-A and UV-B tubes. | F7: 0.4 | G7: 1.8 | H7: C | I7: 0.8 | J7: 0.65 | K7: =_xlfn.CONCAT(LEFT(D7,100),LEFT(E7,100)) -> Fluorescent tubes measuring greater than 2 ft and up to or equal to 4 ftIncludes all diameters and light outputs, shaped fluorescent tubes, and UV-A and UV-B tubes. | L7: =COUNTIF($K$2:K7,K7) -> 2 | M7: =_xlfn.IFNA(_xlfn.CONCAT(VLOOKUP(K7,'ID Generation'!J:K,2,FALSE),100+10*L7+1),"") -> 121111111121
B8: Product Guide | C8: =M8 -> 121111111131 | D8: Fluorescent tubes measuring greater than 2 ft and up to or equal to 4 ft | E8: Includes all diameters and light outputs, shaped fluorescent tubes, and UV-A and UV-B tubes. | F8: 0.4 | G8: 1.8 | H8: C | I8: 0.8 | J8: 0.65 | K8: =_xlfn.CONCAT(LEFT(D8,100),LEFT(E8,100)) -> Fluorescent tubes measuring greater than 2 ft and up to or equal to 4 ftIncludes all diameters and light outputs, shaped fluorescent tubes, and UV-A and UV-B tubes. | L8: =COUNTIF($K$2:K8,K8) -> 3 | M8: =_xlfn.IFNA(_xlfn.CONCAT(VLOOKUP(K8,'ID Generation'!J:K,2,FALSE),100+10*L8+1),"") -> 121111111131
B9: Product Guide | C9: =M9 -> 121111111141 | D9: Fluorescent tubes measuring greater than 2 ft and up to or equal to 4 ft | E9: Includes all diameters and light outputs, shaped fluorescent tubes, and UV-A and UV-B tubes. | F9: 0.4 | G9: 1.8 | H9: C | I9: 0.8 | J9: 0.65 | K9: =_xlfn.CONCAT(LEFT(D9,100),LEFT(E9,100)) -> Fluorescent tubes measuring greater than 2 ft and up to or equal to 4 ftIncludes all diameters and light outputs, shaped fluorescent tubes, and UV-A and UV-B tubes. | L9: =COUNTIF($K$2:K9,K9) -> 4 | M9: =_xlfn.IFNA(_xlfn.CONCAT(VLOOKUP(K9,'ID Generation'!J:K,2,FALSE),100+10*L9+1),"") -> 121111111141
B10: Product Guide | C10: =M10 -> 131111111111 | D10: Fluorescent tubes measuring greater than 4 ft | E10: Includes all diameters and light outputs, shaped fluorescent tubes, and UV-A and UV-B tubes. | F10: 0.8 | G10: 2.5 | H10: C | I10: 1.1 | J10: 1.05 | K10: =_xlfn.CONCAT(LEFT(D10,100),LEFT(E10,100)) -> Fluorescent tubes measuring greater than 4 ftIncludes all diameters and light outputs, shaped fluorescent tubes, and UV-A and UV-B tubes. | L10: =COUNTIF($K$2:K10,K10) -> 1 | M10: =_xlfn.IFNA(_xlfn.CONCAT(VLOOKUP(K10,'ID Generation'!J:K,2,FALSE),100+10*L10+1),"") -> 131111111111
B11: Product Guide | C11: =M11 -> 131111111121 | D11: Fluorescent tubes measuring greater than 4 ft | E11: Includes all diameters and light outputs, shaped fluorescent tubes, and UV-A and UV-B tubes. | F11: 0.8 | G11: 2.5 | H11: C | I11: 1.1 | J11: 1.05 | K11: =_xlfn.CONCAT(LEFT(D11,100),LEFT(E11,100)) -> Fluorescent tubes measuring greater than 4 ftIncludes all diameters and light outputs, shaped fluorescent tubes, and UV-A and UV-B tubes. | L11: =COUNTIF($K$2:K11,K11) -> 2 | M11: =_xlfn.IFNA(_xlfn.CONCAT(VLOOKUP(K11,'ID Generation'!J:K,2,FALSE),100+10*L11+1),"") -> 131111111121
B12: Product Guide | C12: =M12 -> 131111111131 | D12: Fluorescent tubes measuring greater than 4 ft | E12: Includes all diameters and light outputs, shaped fluorescent tubes, and UV-A and UV-B tubes. | F12: 0.8 | G12: 2.5 | H12: C | I12: 1.1 | J12: 1.05 | K12: =_xlfn.CONCAT(LEFT(D12,100),LEFT(E12,100)) -> Fluorescent tubes measuring greater than 4 ftIncludes all diameters and light outputs, shaped fluorescent tubes, and UV-A and UV-B tubes. | L12: =COUNTIF($K$2:K12,K12) -> 3 | M12: =_xlfn.IFNA(_xlfn.CONCAT(VLOOKUP(K12,'ID Generation'!J:K,2,FALSE),100+10*L12+1),"") -> 131111111131
B13: Product Guide | C13: =M13 -> 131111111141 | D13: Fluorescent tubes measuring greater than 4 ft | E13: Includes all diameters and light outputs, shaped fluorescent tubes, and UV-A and UV-B tubes. | F13: 0.8 | G13: 2.5 | H13: C | I13: 1.1 | J13: 1.05 | K13: =_xlfn.CONCAT(LEFT(D13,100),LEFT(E13,100)) -> Fluorescent tubes measuring greater than 4 ftIncludes all diameters and light outputs, shaped fluorescent tubes, and UV-A and UV-B tubes. | L13: =COUNTIF($K$2:K13,K13) -> 4 | M13: =_xlfn.IFNA(_xlfn.CONCAT(VLOOKUP(K13,'ID Generation'!J:K,2,FALSE),100+10*L13+1),"") -> 131111111141
... B18: Product Guide | C18: =M18 -> 141111111151 | D18: Compact Fluorescent Lights (CFL) / Screw-In Induction Lamps | E18: Fluorescent bulbs that are typically similar in size and intended to replace an incandescent (traditional) light bulb, including pin-type sockets, covered CFLs and various output wattages. Includes screw-in induction lamps. | F18: 0.15 | G18: 1 | H18: C | I18: 0.3 | J18: 0.25 | K18: =_xlfn.CONCAT(LEFT(D18,100),LEFT(E18,100)) -> Compact Fluorescent Lights (CFL) / Screw-In Induction LampsFluorescent bulbs that are typically similar in size and intended to replace an incandescent (tradit | L18: =COUNTIF($K$2:K18,K18) -> 5 | M18: =_xlfn.IFNA(_xlfn.CONCAT(VLOOKUP(K18,'ID Generation'!J:K,2,FALSE),100+10*L18+1),"") -> 141111111151
B19: Product Guide | C19: =M19 -> 151111111111 | D19: Light Emitting Diodes (LED) - Bulbs | E19: Solid-state bulbs that are typically similar in size and intended to replace CFLs or traditional incandescent / halogen light bulbs, including pin-type or screw-in bulbs of various output wattages. | F19: 0.15 | H19: C | I19: 0.2 | K19: =_xlfn.CONCAT(LEFT(D19,100),LEFT(E19,100)) -> Light Emitting Diodes (LED) - BulbsSolid-state bulbs that are typically similar in size and intended to replace CFLs or traditional inc | L19: =COUNTIF($K$2:K19,K19) -> 1 | M19: =_xlfn.IFNA(_xlfn.CONCAT(VLOOKUP(K19,'ID Generation'!J:K,2,FALSE),100+10*L19+1),"") -> 151111111111
B20: Product Guide | C20: =M20 -> 151111111121 | D20: Light Emitting Diodes (LED) - Bulbs | E20: Solid-state bulbs that are typically similar in size and intended to replace CFLs or traditional incandescent / halogen light bulbs, including pin-type or screw-in bulbs of various output wattages. | F20: 0.15 | H20: C | I20: 0.2 | K20: =_xlfn.CONCAT(LEFT(D20,100),LEFT(E20,100)) -> Light Emitting Diodes (LED) - BulbsSolid-state bulbs that are typically similar in size and intended to replace CFLs or traditional inc | L20: =COUNTIF($K$2:K20,K20) -> 2 | M20: =_xlfn.IFNA(_xlfn.CONCAT(VLOOKUP(K20,'ID Generation'!J:K,2,FALSE),100+10*L20+1),"") -> 151111111121
B21: Product Guide | C21: =M21 -> 151111111131 | D21: Light Emitting Diodes (LED) - Bulbs | E21: Solid-state bulbs that are typically similar in size and intended to replace CFLs or traditional incandescent / halogen light bulbs, including pin-type or screw-in bulbs of various output wattages. | F21: 0.15 | H21: C | I21: 0.2 | K21: =_xlfn.CONCAT(LEFT(D21,100),LEFT(E21,100)) -> Light Emitting Diodes (LED) - BulbsSolid-state bulbs that are typically similar in size and intended to replace CFLs or traditional inc | L21: =COUNTIF($K$2:K21,K21) -> 3 | M21: =_xlfn.IFNA(_xlfn.CONCAT(VLOOKUP(K21,'ID Generation'!J:K,2,FALSE),100+10*L21+1),"") -> 151111111131
B22: Product Guide | C22: =M22 -> 151111111141 | D22: Light Emitting Diodes (LED) - Bulbs | E22: Solid-state bulbs that are typically similar in size and intended to replace CFLs or traditional incandescent / halogen light bulbs, including pin-type or screw-in bulbs of various output wattages. | F22: 0.15 | H22: C | I22: 0.2 | K22: =_xlfn.CONCAT(LEFT(D22,100),LEFT(E22,100)) -> Light Emitting Diodes (LED) - BulbsSolid-state bulbs that are typically similar in size and intended to replace CFLs or traditional inc | L22: =COUNTIF($K$2:K22,K22) -> 4 | M22: =_xlfn.IFNA(_xlfn.CONCAT(VLOOKUP(K22,'ID Generation'!J:K,2,FALSE),100+10*L22+1),"") -> 151111111141
B23: Product Guide | C23: =M23 -> 151111111151 | D23: Light Emitting Diodes (LED) - Bulbs | E23: Solid-state bulbs that are typically similar in size and intended to replace CFLs or traditional incandescent / halogen light bulbs, including pin-type or screw-in bulbs of various output wattages. | F23: 0.15 | H23: C | I23: 0.2 | K23: =_xlfn.CONCAT(LEFT(D23,100),LEFT(E23,100)) -> Light Emitting Diodes (LED) - BulbsSolid-state bulbs that are typically similar in size and intended to replace CFLs or traditional inc | L23: =COUNTIF($K$2:K23,K23) -> 5 | M23: =_xlfn.IFNA(_xlfn.CONCAT(VLOOKUP(K23,'ID Generation'!J:K,2,FALSE),100+10*L23+1),"") -> 151111111151
B24: Product Guide | C24: =M24 -> 161111111111 | D24: Light Emitting Diodes (LED) - Tubes and Other | E24: Solid-state tubes of all lengths and shapes for all lighting applications, and other lamps / bulbs used for specialty purposes or industrial lighting applications (e.g. LED HID replacement lighting). | H24: C | I24: 0.55 | K24: =_xlfn.CONCAT(LEFT(D24,100),LEFT(E24,100)) -> Light Emitting Diodes (LED) - Tubes and OtherSolid-state tubes of all lengths and shapes for all lighting applications, and other lamps / bulbs u | L24: =COUNTIF($K$2:K24,K24) -> 1 | M24: =_xlfn.IFNA(_xlfn.CONCAT(VLOOKUP(K24,'ID Generation'!J:K,2,FALSE),100+10*L24+1),"") -> 161111111111
B25: Product Guide | C25: =M25 -> 161111111121 | D25: Light Emitting Diodes (LED) - Tubes and Other | E25: Solid-state tubes of all lengths and shapes for all lighting applications, and other lamps / bulbs used for specialty purposes or industrial lighting applications (e.g. LED HID replacement lighting). | H25: C | I25: 0.55 | K25: =_xlfn.CONCAT(LEFT(D25,100),LEFT(E25,100)) -> Light Emitting Diodes (LED) - Tubes and OtherSolid-state tubes of all lengths and shapes for all lighting applications, and other lamps / bulbs u | L25: =COUNTIF($K$2:K25,K25) -> 2 | M25: =_xlfn.IFNA(_xlfn.CONCAT(VLOOKUP(K25,'ID Generation'!J:K,2,FALSE),100+10*L25+1),"") -> 161111111121
B26: Product Guide | C26: =M26 -> 161111111131 | D26: Light Emitting Diodes (LED) - Tubes and Other | E26: Solid-state tubes of all lengths and shapes for all lighting applications, and other lamps / bulbs used for specialty purposes or industrial lighting applications (e.g. LED HID replacement lighting). | H26: C | I26: 0.55 | K26: =_xlfn.CONCAT(LEFT(D26,100),LEFT(E26,100)) -> Light Emitting Diodes (LED) - Tubes and OtherSolid-state tubes of all lengths and shapes for all lighting applications, and other lamps / bulbs u | L26: =COUNTIF($K$2:K26,K26) -> 3 | M26: =_xlfn.IFNA(_xlfn.CONCAT(VLOOKUP(K26,'ID Generation'!J:K,2,FALSE),100+10*L26+1),"") -> 161111111131
B27: Product Guide | C27: =M27 -> 161111111141 | D27: Light Emitting Diodes (LED) - Tubes and Other | E27: Solid-state tubes of all lengths and shapes for all lighting applications, and other lamps / bulbs used for specialty purposes or industrial lighting applications (e.g. LED HID replacement lighting). | H27: C | I27: 0.55 | K27: =_xlfn.CONCAT(LEFT(D27,100),LEFT(E27,100)) -> Light Emitting Diodes (LED) - Tubes and OtherSolid-state tubes of all lengths and shapes for all lighting applications, and other lamps / bulbs u | L27: =COUNTIF($K$2:K27,K27) -> 4 | M27: =_xlfn.IFNA(_xlfn.CONCAT(VLOOKUP(K27,'ID Generation'!J:K,2,FALSE),100+10*L27+1),"") -> 161111111141
B28: Product Guide | C28: =M28 -> 171111111111 | D28: High Intensity Discharge (HID), Germicidal, Special Purpose and Other | E28: Includes all HID technologies that contain mercury, such as High-Pressure Sodium (HPS), Low-Pressure Sodium (LPS), Mercury Vapor and Metal Halide, as well as UV-C / Germicidal lamps and tubes, Tubular Induction lamps (circular, square, U etc.), UHP replacement lamps (projector etc.), Neon replacement lamps, etc. | F28: 1.1 | H28: C | I28: 1.65 | J28: 1.35 | K28: =_xlfn.CONCAT(LEFT(D28,100),LEFT(E28,100)) -> High Intensity Discharge (HID), Germicidal, Special Purpose and OtherIncludes all HID technologies that contain mercury, such as High-Pressure Sodium (HPS), Low-Pressure | L28: =COUNTIF($K$2:K28,K28) -> 1 | M28: =_xlfn.IFNA(_xlfn.CONCAT(VLOOKUP(K28,'ID Generation'!J:K,2,FALSE),100+10*L28+1),"") -> 171111111111
B29: Product Guide | C29: =M29 -> 171111111121 | D29: High Intensity Discharge (HID), Germicidal, Special Purpose and Other | E29: Includes all HID technologies that contain mercury, such as High-Pressure Sodium (HPS), Low-Pressure Sodium (LPS), Mercury Vapor and Metal Halide, as well as UV-C / Germicidal lamps and tubes, Tubular Induction lamps (circular, square, U etc.), UHP replacement lamps (projector etc.), Neon replacement lamps, etc. | F29: 1.1 | H29: C | I29: 1.65 | J29: 1.35 | K29: =_xlfn.CONCAT(LEFT(D29,100),LEFT(E29,100)) -> High Intensity Discharge (HID), Germicidal, Special Purpose and OtherIncludes all HID technologies that contain mercury, such as High-Pressure Sodium (HPS), Low-Pressure | L29: =COUNTIF($K$2:K29,K29) -> 2 | M29: =_xlfn.IFNA(_xlfn.CONCAT(VLOOKUP(K29,'ID Generation'!J:K,2,FALSE),100+10*L29+1),"") -> 171111111121
B30: Product Guide | C30: =M30 -> 171111111131 | D30: High Intensity Discharge (HID), Germicidal, Special Purpose and Other | E30: Includes all HID technologies that contain mercury, such as High-Pressure Sodium (HPS), Low-Pressure Sodium (LPS), Mercury Vapor and Metal Halide, as well as UV-C / Germicidal lamps and tubes, Tubular Induction lamps (circular, square, U etc.), UHP replacement lamps (projector etc.), Neon replacement lamps, etc. | F30: 1.1 | H30: C | I30: 1.65 | J30: 1.35 | K30: =_xlfn.CONCAT(LEFT(D30,100),LEFT(E30,100)) -> High Intensity Discharge (HID), Germicidal, Special Purpose and OtherIncludes all HID technologies that contain mercury, such as High-Pressure Sodium (HPS), Low-Pressure | L30: =COUNTIF($K$2:K30,K30) -> 3 | M30: =_xlfn.IFNA(_xlfn.CONCAT(VLOOKUP(K30,'ID Generation'!J:K,2,FALSE),100+10*L30+1),"") -> 171111111131
B31: Product Guide | C31: =M31 -> 171111111141 | D31: High Intensity Discharge (HID), Germicidal, Special Purpose and Other | E31: Includes all HID technologies that contain mercury, such as High-Pressure Sodium (HPS), Low-Pressure Sodium (LPS), Mercury Vapor and Metal Halide, as well as UV-C / Germicidal lamps and tubes, Tubular Induction lamps (circular, square, U etc.), UHP replacement lamps (projector etc.), Neon replacement lamps, etc. | F31: 1.1 | H31: C | I31: 1.65 | J31: 1.35 | K31: =_xlfn.CONCAT(LEFT(D31,100),LEFT(E31,100)) -> High Intensity Discharge (HID), Germicidal, Special Purpose and OtherIncludes all HID technologies that contain mercury, such as High-Pressure Sodium (HPS), Low-Pressure | L31: =COUNTIF($K$2:K31,K31) -> 4 | M31: =_xlfn.IFNA(_xlfn.CONCAT(VLOOKUP(K31,'ID Generation'!J:K,2,FALSE),100+10*L31+1),"") -> 171111111141
B32: Product Guide | C32: =M32 -> 171111111151 | D32: High Intensity Discharge (HID), Germicidal, Special Purpose and Other | E32: Includes all HID technologies that contain mercury, such as High-Pressure Sodium (HPS), Low-Pressure Sodium (LPS), Mercury Vapor and Metal Halide, as well as UV-C / Germicidal lamps and tubes, Tubular Induction lamps (circular, square, U etc.), UHP replacement lamps (projector etc.), Neon replacement lamps, etc. | F32: 1.1 | H32: C | I32: 1.65 | J32: 1.35 | K32: =_xlfn.CONCAT(LEFT(D32,100),LEFT(E32,100)) -> High Intensity Discharge (HID), Germicidal, Special Purpose and OtherIncludes all HID technologies that contain mercury, such as High-Pressure Sodium (HPS), Low-Pressure | L32: =COUNTIF($K$2:K32,K32) -> 5 | M32: =_xlfn.IFNA(_xlfn.CONCAT(VLOOKUP(K32,'ID Generation'!J:K,2,FALSE),100+10*L32+1),"") -> 171111111151
B33: Product Guide | C33: =M33 -> 171111111161 | D33: High Intensity Discharge (HID), Germicidal, Special Purpose and Other | E33: Includes all HID technologies that contain mercury, such as High-Pressure Sodium (HPS), Low-Pressure Sodium (LPS), Mercury Vapor and Metal Halide, as well as UV-C / Germicidal lamps and tubes, Tubular Induction lamps (circular, square, U etc.), UHP replacement lamps (projector etc.), Neon replacement lamps, etc. | F33: 1.1 | H33: C | I33: 1.65 | J33: 1.35 | K33: =_xlfn.CONCAT(LEFT(D33,100),LEFT(E33,100)) -> High Intensity Discharge (HID), Germicidal, Special Purpose and OtherIncludes all HID technologies that contain mercury, such as High-Pressure Sodium (HPS), Low-Pressure | L33: =COUNTIF($K$2:K33,K33) -> 6 | M33: =_xlfn.IFNA(_xlfn.CONCAT(VLOOKUP(K33,'ID Generation'!J:K,2,FALSE),100+10*L33+1),"") -> 171111111161
B34: Product Guide | C34: =M34 -> 171111111171 | D34: High Intensity Discharge (HID), Germicidal, Special Purpose and Other | E34: Includes all HID technologies that contain mercury, such as High-Pressure Sodium (HPS), Low-Pressure Sodium (LPS), Mercury Vapor and Metal Halide, as well as UV-C / Germicidal lamps and tubes, Tubular Induction lamps (circular, square, U etc.), UHP replacement lamps (projector etc.), Neon replacement lamps, etc. | F34: 1.1 | H34: C | I34: 1.65 | J34: 1.35 | K34: =_xlfn.CONCAT(LEFT(D34,100),LEFT(E34,100)) -> High Intensity Discharge (HID), Germicidal, Special Purpose and OtherIncludes all HID technologies that contain mercury, such as High-Pressure Sodium (HPS), Low-Pressure | L34: =COUNTIF($K$2:K34,K34) -> 7 | M34: =_xlfn.IFNA(_xlfn.CONCAT(VLOOKUP(K34,'ID Generation'!J:K,2,FALSE),100+10*L34+1),"") -> 171111111171
B35: Product Guide | C35: =M35 -> 181111111111 | D35: Incandescent / Halogen | E35: Filament lamps of all shapes, sizes and wattages | F35: 0.05 | H35: C | I35: 0.2 | K35: =_xlfn.CONCAT(LEFT(D35,100),LEFT(E35,100)) -> Incandescent / HalogenFilament lamps of all shapes, sizes and wattages | L35: =COUNTIF($K$2:K35,K35) -> 1 | M35: =_xlfn.IFNA(_xlfn.CONCAT(VLOOKUP(K35,'ID Generation'!J:K,2,FALSE),100+10*L35+1),"") -> 181111111111
B36: Product Guide | C36: =M36 -> 181111111121 | D36: Incandescent / Halogen | E36: Filament lamps of all shapes, sizes and wattages | F36: 0.05 | H36: C | I36: 0.2 | K36: =_xlfn.CONCAT(LEFT(D36,100),LEFT(E36,100)) -> Incandescent / HalogenFilament lamps of all shapes, sizes and wattages | L36: =COUNTIF($K$2:K36,K36) -> 2 | M36: =_xlfn.IFNA(_xlfn.CONCAT(VLOOKUP(K36,'ID Generation'!J:K,2,FALSE),100+10*L36+1),"") -> 181111111121
B37: Product Guide | C37: =M37 -> 181111111131 | D37: Incandescent / Halogen | E37: Filament lamps of all shapes, sizes and wattages | F37: 0.05 | H37: C | I37: 0.2 | K37: =_xlfn.CONCAT(LEFT(D37,100),LEFT(E37,100)) -> Incandescent / HalogenFilament lamps of all shapes, sizes and wattages | L37: =COUNTIF($K$2:K37,K37) -> 3 | M37: =_xlfn.IFNA(_xlfn.CONCAT(VLOOKUP(K37,'ID Generation'!J:K,2,FALSE),100+10*L37+1),"") -> 181111111131
B38: Product Guide | C38: =M38 -> 181111111141 | D38: Incandescent / Halogen | E38: Filament lamps of all shapes, sizes and wattages | F38: 0.05 | H38: C | I38: 0.2 | K38: =_xlfn.CONCAT(LEFT(D38,100),LEFT(E38,100)) -> Incandescent / HalogenFilament lamps of all shapes, sizes and wattages | L38: =COUNTIF($K$2:K38,K38) -> 4 | M38: =_xlfn.IFNA(_xlfn.CONCAT(VLOOKUP(K38,'ID Generation'!J:K,2,FALSE),100+10*L38+1),"") -> 181111111141
B39: Product Guide | C39: =M39 -> 181111111151 | D39: Incandescent / Halogen | E39: Filament lamps of all shapes, sizes and wattages | F39: 0.05 | H39: C | I39: 0.2 | K39: =_xlfn.CONCAT(LEFT(D39,100),LEFT(E39,100)) -> Incandescent / HalogenFilament lamps of all shapes, sizes and wattages | L39: =COUNTIF($K$2:K39,K39) -> 5 | M39: =_xlfn.IFNA(_xlfn.CONCAT(VLOOKUP(K39,'ID Generation'!J:K,2,FALSE),100+10*L39+1),"") -> 181111111151
B40: Product Guide | C40: =M40 -> 191111111111 | D40: Miniature Bulb Package | E40: Miniature bulbs are small, or very small bulbs. They can be LED, incandescent, halogen or neon and are typically designed and sold as replacement bulbs for applications such as: portable lighting (i.e., handheld flashlights), indicating, signaling, signage, emergency, electronic displays, automotive and transportation and decorative light strings / tape / ribbon / rope. | F40: 0.1 | H40: C | I40: 0.2 | K40: =_xlfn.CONCAT(LEFT(D40,100),LEFT(E40,100)) -> Miniature Bulb PackageMiniature bulbs are small, or very small bulbs. They can be LED, incandescent, halogen or neon and a | L40: =COUNTIF($K$2:K40,K40) -> 1 | M40: =_xlfn.IFNA(_xlfn.CONCAT(VLOOKUP(K40,'ID Generation'!J:K,2,FALSE),100+10*L40+1),"") -> 191111111111
B41: Product Guide | C41: =M41 -> 191111111121 | D41: Miniature Bulb Package | E41: Miniature bulbs are small, or very small bulbs. They can be LED, incandescent, halogen or neon and are typically designed and sold as replacement bulbs for applications such as: portable lighting (i.e., handheld flashlights), indicating, signaling, signage, emergency, electronic displays, automotive and transportation and decorative light strings / tape / ribbon / rope. | F41: 0.1 | H41: C | I41: 0.2 | K41: =_xlfn.CONCAT(LEFT(D41,100),LEFT(E41,100)) -> Miniature Bulb PackageMiniature bulbs are small, or very small bulbs. They can be LED, incandescent, halogen or neon and a | L41: =COUNTIF($K$2:K41,K41) -> 2 | M41: =_xlfn.IFNA(_xlfn.CONCAT(VLOOKUP(K41,'ID Generation'!J:K,2,FALSE),100+10*L41+1),"") -> 191111111121
B42: Product Guide | C42: =M42 -> 191111111131 | D42: Miniature Bulb Package | E42: Miniature bulbs are small, or very small bulbs. They can be LED, incandescent, halogen or neon and are typically designed and sold as replacement bulbs for applications such as: portable lighting (i.e., handheld flashlights), indicating, signaling, signage, emergency, electronic displays, automotive and transportation and decorative light strings / tape / ribbon / rope. | F42: 0.1 | H42: C | I42: 0.2 | K42: =_xlfn.CONCAT(LEFT(D42,100),LEFT(E42,100)) -> Miniature Bulb PackageMiniature bulbs are small, or very small bulbs. They can be LED, incandescent, halogen or neon and a | L42: =COUNTIF($K$2:K42,K42) -> 3 | M42: =_xlfn.IFNA(_xlfn.CONCAT(VLOOKUP(K42,'ID Generation'!J:K,2,FALSE),100+10*L42+1),"") -> 191111111131
B43: Product Guide | C43: =M43 -> 191111111141 | D43: Miniature Bulb Package | E43: Miniature bulbs are small, or very small bulbs. They can be LED, incandescent, halogen or neon and are typically designed and sold as replacement bulbs for applications such as: portable lighting (i.e., handheld flashlights), indicating, signaling, signage, emergency, electronic displays, automotive and transportation and decorative light strings / tape / ribbon / rope. | F43: 0.1 | H43: C | I43: 0.2 | K43: =_xlfn.CONCAT(LEFT(D43,100),LEFT(E43,100)) -> Miniature Bulb PackageMiniature bulbs are small, or very small bulbs. They can be LED, incandescent, halogen or neon and a | L43: =COUNTIF($K$2:K43,K43) -> 4 | M43: =_xlfn.IFNA(_xlfn.CONCAT(VLOOKUP(K43,'ID Generation'!J:K,2,FALSE),100+10*L43+1),"") -> 191111111141
B44: Product Guide | C44: =M44 -> 191111111151 | D44: Miniature Bulb Package | E44: Miniature bulbs are small, or very small bulbs. They can be LED, incandescent, halogen or neon and are typically designed and sold as replacement bulbs for applications such as: portable lighting (i.e., handheld flashlights), indicating, signaling, signage, emergency, electronic displays, automotive and transportation and decorative light strings / tape / ribbon / rope. | F44: 0.1 | H44: C | I44: 0.2 | K44: =_xlfn.CONCAT(LEFT(D44,100),LEFT(E44,100)) -> Miniature Bulb PackageMiniature bulbs are small, or very small bulbs. They can be LED, incandescent, halogen or neon and a | L44: =COUNTIF($K$2:K44,K44) -> 5 | M44: =_xlfn.IFNA(_xlfn.CONCAT(VLOOKUP(K44,'ID Generation'!J:K,2,FALSE),100+10*L44+1),"") -> 191111111151
...

Sheet ID Generation
A1: id | B1: main_category_id | C1: main_category | D1: id inside MC | E1: product_category_id | F1: product_category | G1: id inside PC | H1: product_description_id | I1: product_description | J1: c1 | K1: c2
A2: 1 | B2: =100+10*A2+1 -> 111 | C2: Tubes (less than or equal to 2 feet) | D2: 1 | E2: =_xlfn.CONCAT(B2,100+10*D2+1) -> 111111 | F2: Fluorescent tubes measuring less than or equal to 2 ft | G2: 1 | H2: =_xlfn.CONCAT(E2,100+10*G2+1) -> 111111111 | I2: Includes all diameters and light outputs, shaped fluorescent tubes, and UV-A and UV-B tubes. | J2: =_xlfn.CONCAT(LEFT(F2,100),LEFT(I2,100)) -> Fluorescent tubes measuring less than or equal to 2 ftIncludes all diameters and light outputs, shaped fluorescent tubes, and UV-A and UV-B tubes. | K2: =H2 -> 111111111
A3: 2 | B3: =100+10*A3+1 -> 121 | C3: Tubes (greater than 2 feet and up to or equal to 4 feet) | D3: 1 | E3: =_xlfn.CONCAT(B3,100+10*D3+1) -> 121111 | F3: Fluorescent tubes measuring greater than 2 ft and up to or equal to 4 ft | G3: 1 | H3: =_xlfn.CONCAT(E3,100+10*G3+1) -> 121111111 | I3: Includes all diameters and light outputs, shaped fluorescent tubes, and UV-A and UV-B tubes. | J3: =_xlfn.CONCAT(LEFT(F3,100),LEFT(I3,100)) -> Fluorescent tubes measuring greater than 2 ft and up to or equal to 4 ftIncludes all diameters and light outputs, shaped fluorescent tubes, and UV-A and UV-B tubes. | K3: =H3 -> 121111111
A4: 3 | B4: =100+10*A4+1 -> 131 | C4: Tubes (greater than 4 feet) | D4: 1 | E4: =_xlfn.CONCAT(B4,100+10*D4+1) -> 131111 | F4: Fluorescent tubes measuring greater than 4 ft | G4: 1 | H4: =_xlfn.CONCAT(E4,100+10*G4+1) -> 131111111 | I4: Includes all diameters and light outputs, shaped fluorescent tubes, and UV-A and UV-B tubes. | J4: =_xlfn.CONCAT(LEFT(F4,100),LEFT(I4,100)) -> Fluorescent tubes measuring greater than 4 ftIncludes all diameters and light outputs, shaped fluorescent tubes, and UV-A and UV-B tubes. | K4: =H4 -> 131111111
A5: 4 | B5: =100+10*A5+1 -> 141 | C5: Compact fluorescent lights (CFL) / Screw-in induction lamps | D5: 1 | E5: =_xlfn.CONCAT(B5,100+10*D5+1) -> 141111 | F5: Compact Fluorescent Lights (CFL) / Screw-In Induction Lamps | G5: 1 | H5: =_xlfn.CONCAT(E5,100+10*G5+1) -> 141111111 | I5: Fluorescent bulbs that are typically similar in size and intended to replace an incandescent (traditional) light bulb, including pin-type sockets, covered CFLs and various output wattages. Includes screw-in induction lamps. | J5: =_xlfn.CONCAT(LEFT(F5,100),LEFT(I5,100)) -> Compact Fluorescent Lights (CFL) / Screw-In Induction LampsFluorescent bulbs that are typically similar in size and intended to replace an incandescent (tradit | K5: =H5 -> 141111111
A6: 5 | B6: =100+10*A6+1 -> 151 | C6: Light emitting diodes (LED) | D6: 1 | E6: =_xlfn.CONCAT(B6,100+10*D6+1) -> 151111 | F6: Light Emitting Diodes (LED) - Bulbs | G6: 1 | H6: =_xlfn.CONCAT(E6,100+10*G6+1) -> 151111111 | I6: Solid-state bulbs that are typically similar in size and intended to replace CFLs or traditional incandescent / halogen light bulbs, including pin-type or screw-in bulbs of various output wattages. | J6: =_xlfn.CONCAT(LEFT(F6,100),LEFT(I6,100)) -> Light Emitting Diodes (LED) - BulbsSolid-state bulbs that are typically similar in size and intended to replace CFLs or traditional inc | K6: =H6 -> 151111111
A7: 6 | B7: =100+10*A7+1 -> 161 | C7: Light emitting diodes (LED) - Tubes and Others | D7: 1 | E7: =_xlfn.CONCAT(B7,100+10*D7+1) -> 161111 | F7: Light Emitting Diodes (LED) - Tubes and Other | G7: 1 | H7: =_xlfn.CONCAT(E7,100+10*G7+1) -> 161111111 | I7: Solid-state tubes of all lengths and shapes for all lighting applications, and other lamps / bulbs used for specialty purposes or industrial lighting applications (e.g. LED HID replacement lighting). | J7: =_xlfn.CONCAT(LEFT(F7,100),LEFT(I7,100)) -> Light Emitting Diodes (LED) - Tubes and OtherSolid-state tubes of all lengths and shapes for all lighting applications, and other lamps / bulbs u | K7: =H7 -> 161111111
A8: 7 | B8: =100+10*A8+1 -> 171 | C8: High intensity discharge (HID) and other: UV, Germicidal, UHP, Neon, etc | D8: 1 | E8: =_xlfn.CONCAT(B8,100+10*D8+1) -> 171111 | F8: High Intensity Discharge (HID), Germicidal, Special Purpose and Other | G8: 1 | H8: =_xlfn.CONCAT(E8,100+10*G8+1) -> 171111111 | I8: Includes all HID technologies that contain mercury, such as High-Pressure Sodium (HPS), Low-Pressure Sodium (LPS), Mercury Vapor and Metal Halide, as well as UV-C / Germicidal lamps and tubes, Tubular Induction lamps (circular, square, U etc.), UHP replacement lamps (projector etc.), Neon replacement lamps, etc. | J8: =_xlfn.CONCAT(LEFT(F8,100),LEFT(I8,100)) -> High Intensity Discharge (HID), Germicidal, Special Purpose and OtherIncludes all HID technologies that contain mercury, such as High-Pressure Sodium (HPS), Low-Pressure | K8: =H8 -> 171111111
A9: 8 | B9: =100+10*A9+1 -> 181 | C9: Incandescent / Halogen | D9: 1 | E9: =_xlfn.CONCAT(B9,100+10*D9+1) -> 181111 | F9: Incandescent / Halogen | G9: 1 | H9: =_xlfn.CONCAT(E9,100+10*G9+1) -> 181111111 | I9: Filament lamps of all shapes, sizes and wattages | J9: =_xlfn.CONCAT(LEFT(F9,100),LEFT(I9,100)) -> Incandescent / HalogenFilament lamps of all shapes, sizes and wattages | K9: =H9 -> 181111111
A10: 9 | B10: =100+10*A10+1 -> 191 | C10: Miniature bulb package | D10: 1 | E10: =_xlfn.CONCAT(B10,100+10*D10+1) -> 191111 | F10: Miniature Bulb Package | G10: 1 | H10: =_xlfn.CONCAT(E10,100+10*G10+1) -> 191111111 | I10: Miniature bulbs are small, or very small bulbs. They can be LED, incandescent, halogen or neon and are typically designed and sold as replacement bulbs for applications such as: portable lighting (i.e., handheld flashlights), indicating, signaling, signage, emergency, electronic displays, automotive and transportation and decorative light strings / tape / ribbon / rope. | J10: =_xlfn.CONCAT(LEFT(F10,100),LEFT(I10,100)) -> Miniature Bulb PackageMiniature bulbs are small, or very small bulbs. They can be LED, incandescent, halogen or neon and a | K10: =H10 -> 191111111
A11: 10 | B11: =100+10*A11+1 -> 201 | C11: Lighting fixtures and products | D11: 1 | E11: =_xlfn.CONCAT(B11,100+10*D11+1) -> 201111 | F11: Designated Small Fixtures / Decorative Light Strings | G11: 1 | H11: =_xlfn.CONCAT(E11,100+10*G11+1) -> 201111111 | I11: Book Lights (including Kindle Lights) | J11: =_xlfn.CONCAT(LEFT(F11,100),LEFT(I11,100)) -> Designated Small Fixtures / Decorative Light StringsBook Lights (including Kindle Lights) | K11: =H11 -> 201111111
A12: 10 | B12: =100+10*A12+1 -> 201 | C12: Lighting fixtures and products | D12: 1 | E12: =_xlfn.CONCAT(B12,100+10*D12+1) -> 201111 | F12: Designated Small Fixtures / Decorative Light Strings | G12: 2 | H12: =_xlfn.CONCAT(E12,100+10*G12+1) -> 201111121 | I12: Snake Lights | J12: =_xlfn.CONCAT(LEFT(F12,100),LEFT(I12,100)) -> Designated Small Fixtures / Decorative Light StringsSnake Lights | K12: =H12 -> 201111121
A13: 10 | B13: =100+10*A13+1 -> 201 | C13: Lighting fixtures and products | D13: 1 | E13: =_xlfn.CONCAT(B13,100+10*D13+1) -> 201111 | F13: Designated Small Fixtures / Decorative Light Strings | G13: 3 | H13: =_xlfn.CONCAT(E13,100+10*G13+1) -> 201111131 | I13: Bike Lights | J13: =_xlfn.CONCAT(LEFT(F13,100),LEFT(I13,100)) -> Designated Small Fixtures / Decorative Light StringsBike Lights | K13: =H13 -> 201111131
... A58: 11 | B58: =100+10*A58+1 -> 211 | C58: Ballasts | D58: 1 | E58: =_xlfn.CONCAT(B58,100+10*D58+1) -> 211111 | F58: Lighting Ballasts / Transformers (not integrated into lamps or fixtures) | G58: 1 | H58: =_xlfn.CONCAT(E58,100+10*G58+1) -> 211111111 | I58: Ballasts, all types (i.e., compact fluorescent, electronic, HID, magnetic etc.) | J58: =_xlfn.CONCAT(LEFT(F58,100),LEFT(I58,100)) -> Lighting Ballasts / Transformers (not integrated into lamps or fixtures)Ballasts, all types (i.e., compact fluorescent, electronic, HID, magnetic etc.) | K58: =H58 -> 211111111

Sheet Old - Main Category
A1: ID | B1: Main Category ID | C1: Main Category
A2: 1 | B2: =A2*5-4 -> 1 | C2: Tubes (less than or equal to 2 feet)
A3: 2 | B3: =A3*5-4 -> 6 | C3: Tubes (greater than 2 feet and up to or equal to 4 feet)
A4: 3 | B4: =A4*5-4 -> 11 | C4: Tubes (greater than 4 feet)
A5: 4 | B5: =A5*5-4 -> 16 | C5: Compact fluorescent lights (CFL) / Screw-in induction lamps
A6: 5 | B6: =A6*5-4 -> 21 | C6: Light emitting diodes (LED)
A7: 6 | B7: =A7*5-4 -> 26 | C7: Light emitting diodes (LED) - Tubes and Others
A8: 7 | B8: =A8*5-4 -> 31 | C8: High intensity discharge (HID) and other: UV, Germicidal, UHP, Neon, etc
A9: 8 | B9: =A9*5-4 -> 36 | C9: Incandescent / Halogen
A10: 9 | B10: =A10*5-4 -> 41 | C10: Miniature bulb package
A11: 10 | B11: =A11*5-4 -> 46 | C11: Lighting fixtures and products
A12: 11 | B12: =A12*5-4 -> 51 | C12: Ballasts

Sheet Old - Edit
A1: ID | B1: Main Category ID | C1: MCI * 100 | D1: MCI* 100 + 1000 | E1: Sub Category ID within Main Category | F1: product_category_id | G1: product_category | H1: product_description | I1: British Columbia | J1: Manitoba | K1: Ontario | L1: Prince Edward Island | M1: Québec
A2: 1 | B2: =A2*5-4 -> 1 | C2: =B2*100 -> 100 | D2: =C2+1000 -> 1100 | E2: 1 | F2: =D2+E2 -> 1101 | G2: Fluorescent tubes measuring less than or equal to 2 ft | H2: Includes all diameters and light outputs, shaped fluorescent tubes, and UV-A and UV-B tubes. | I2: 4 | J2: 4 | K2: 4 | L2: 4 | M2: 4
A3: 2 | B3: =A3*5-4 -> 6 | C3: =B3*100 -> 600 | D3: =C3+1000 -> 1600 | E3: 1 | F3: =D3+E3 -> 1601 | G3: Fluorescent tubes measuring greater than 2 ft and up to or equal to 4 ft | H3: Includes all diameters and light outputs, shaped fluorescent tubes, and UV-A and UV-B tubes. | I3: 4 | J3: 4 | K3: 4 | L3: 4 | M3: 4
A4: 3 | B4: =A4*5-4 -> 11 | C4: =B4*100 -> 1100 | D4: =C4+1000 -> 2100 | E4: 1 | F4: =D4+E4 -> 2101 | G4: Fluorescent tubes measuring greater than 4 ft | H4: Includes all diameters and light outputs, shaped fluorescent tubes, and UV-A and UV-B tubes. | I4: 4 | J4: 4 | K4: 4 | L4: 4 | M4: 4
A5: 4 | B5: =A5*5-4 -> 16 | C5: =B5*100 -> 1600 | D5: =C5+1000 -> 2600 | E5: 1 | F5: =D5+E5 -> 2601 | G5: Compact Fluorescent Lights (CFL) / Screw-In Induction Lamps | H5: Fluorescent bulbs that are typically similar in size and intended to replace an incandescent (traditional) light bulb, including pin-type sockets, covered CFLs and various output wattages. Includes screw-in induction lamps. | I5: 4 | J5: 4 | K5: 5 | L5: 4 | M5: 4
A6: 5 | B6: =A6*5-4 -> 21 | C6: =B6*100 -> 2100 | D6: =C6+1000 -> 3100 | E6: 1 | F6: =D6+E6 -> 3101 | G6: Light Emitting Diodes (LED) - Bulbs | H6: Solid-state bulbs that are typically similar in size and intended to replace CFLs or traditional incandescent / halogen light bulbs, including pin-type or screw-in bulbs of various output wattages. | K6: 5
A7: 5 | B7: =A7*5-4 -> 21 | C7: =B7*100 -> 2100 | D7: =C7+1000 -> 3100 | E7: 2 | F7: =D7+E7 -> 3102 | G7: Light Emitting Diodes | H7: Solid-state lamps used for specialty purposes and conventional lighting applications. | I7: 4 | L7: 3
A8: 6 | B8: =A8*5-4 -> 26 | C8: =B8*100 -> 2600 | D8: =C8+1000 -> 3600 | E8: 1 | F8: =D8+E8 -> 3601 | G8: Light Emitting Diodes (LED) - Tubes and Other | H8: Solid-state tubes of all lengths and shapes for all lighting applications, and other lamps / bulbs used for specialty purposes or industrial lighting applications (e.g. LED HID replacement lighting). | K8: 4 | L8: 4
A9: 7 | B9: =A9*5-4 -> 31 | C9: =B9*100 -> 3100 | D9: =C9+1000 -> 4100 | E9: 1 | F9: =D9+E9 -> 4101 | G9: High Intensity Discharge (HID), Germicidal, Special Purpose and Other | H9: Includes all HID technologies that contain mercury, such as High-Pressure Sodium (HPS), Low-Pressure Sodium (LPS), Mercury Vapor and Metal Halide, as well as UV-C / Germicidal lamps and tubes, Tubular Induction lamps (circular, square, U etc.), UHP replacement lamps (projector etc.), Neon replacement lamps, etc. | I9: 4 | K9: 4 | L9: 4 | M9: 4
A10: 8 | B10: =A10*5-4 -> 36 | C10: =B10*100 -> 3600 | D10: =C10+1000 -> 4600 | E10: 1 | F10: =D10+E10 -> 4601 | G10: Incandescent / Halogen | H10: Filament lamps of all shapes, sizes and wattages | I10: 4 | K10: 5 | L10: 4
A11: 9 | B11: =A11*5-4 -> 41 | C11: =B11*100 -> 4100 | D11: =C11+1000 -> 5100 | E11: 1 | F11: =D11+E11 -> 5101 | G11: Miniature Bulb Package | H11: Miniature bulbs are small, or very small bulbs. They can be LED, incandescent, halogen or neon and are typically designed and sold as replacement bulbs for applications such as: portable lighting (i.e., handheld flashlights), indicating, signaling, signage, emergency, electronic displays, automotive and transportation and decorative light strings / tape / ribbon / rope. | I11: 8 | K11: 8 | L11: 8
A12: 10 | B12: =A12*5-4 -> 46 | C12: =B12*100 -> 4600 | D12: =C12+1000 -> 5600 | E12: 1 | F12: =D12+E12 -> 5601 | G12: Designated Small Fixtures / Decorative Light Strings | H12: Bike Lights | I12: 4
A13: 10 | B13: =A13*5-4 -> 46 | C13: =B13*100 -> 4600 | D13: =C13+1000 -> 5600 | E13: 1 | F13: =D13+E13 -> 5601 | G13: Designated Small Fixtures / Decorative Light Strings | H13: Book Lights (including Kindle Lights) | I13: 4
A14: 10 | B14: =A14*5-4 -> 46 | C14: =B14*100 -> 4600 | D14: =C14+1000 -> 5600 | E14: 1 | F14: =D14+E14 -> 5601 | G14: Designated Small Fixtures / Decorative Light Strings | H14: Christmas Light Strings and Light Strings Products are reported and applied fees in increments of 100 lights. Products of 100 lights or less are applied for one recycling fee. Products with greater than 100 lights are charged one recycling fee per 100 light increments. For example, a light string of 460 lights would be reported as 5 units and assessed five fees. | I14: 4
A15: 10 | B15: =A15*5-4 -> 46 | C15: =B15*100 -> 4600 | D15: =C15+1000 -> 5600 | E15: 1 | F15: =D15+E15 -> 5601 | G15: Designated Small Fixtures / Decorative Light Strings | H15: Clamp Spotlights and Clip Lamps | I15: 4
A16: 10 | B16: =A16*5-4 -> 46 | C16: =B16*100 -> 4600 | D16: =C16+1000 -> 5600 | E16: 1 | F16: =D16+E16 -> 5601 | G16: Designated Small Fixtures / Decorative Light Strings | H16: Flashlights, Camping Headlamps, and Handheld Spotlights | I16: 4
A17: 10 | B17: =A17*5-4 -> 46 | C17: =B17*100 -> 4600 | D17: =C17+1000 -> 5600 | E17: 1 | F17: =D17+E17 -> 5601 | G17: Designated Small Fixtures / Decorative Light Strings | H17: Floating / Submersible Lights for pools, ponds, bathtubs, etc. (portable and battery powered only) | I17: 4
A18: 10 | B18: =A18*5-4 -> 46 | C18: =B18*100 -> 4600 | D18: =C18+1000 -> 5600 | E18: 1 | F18: =D18+E18 -> 5601 | G18: Designated Small Fixtures / Decorative Light Strings | H18: Lamp-holders (stand-alone and single lamp only) | I18: 4
A19: 10 | B19: =A19*5-4 -> 46 | C19: =B19*100 -> 4600 | D19: =C19+1000 -> 5600 | E19: 1 | F19: =D19+E19 -> 5601 | G19: Designated Small Fixtures / Decorative Light Strings | H19: Lanterns and Electric Candles | I19: 4
A20: 10 | B20: =A20*5-4 -> 46 | C20: =B20*100 -> 4600 | D20: =C20+1000 -> 5600 | E20: 1 | F20: =D20+E20 -> 5601 | G20: Designated Small Fixtures / Decorative Light Strings | H20: Night Lights | I20: 4
A21: 10 | B21: =A21*5-4 -> 46 | C21: =B21*100 -> 4600 | D21: =C21+1000 -> 5600 | E21: 1 | F21: =D21+E21 -> 5601 | G21: Designated Small Fixtures / Decorative Light Strings | H21: Path / Walkway / Garden / In-Grade / Border / Step Lights (solar powered only) | I21: 4
A22: 10 | B22: =A22*5-4 -> 46 | C22: =B22*100 -> 4600 | D22: =C22+1000 -> 5600 | E22: 1 | F22: =D22+E22 -> 5601 | G22: Designated Small Fixtures / Decorative Light Strings | H22: Puck / Disk Lights Compact lighting fixture used for cabinets or display lighting that contains the housing and lamp in a circular (round or oval) “puck” or “disk”. May be surface mounted or recessed. Limited to those under 4 inches in diameter and 2 inches in depth. | I22: 4
A23: 10 | B23: =A23*5-4 -> 46 | C23: =B23*100 -> 4600 | D23: =C23+1000 -> 5600 | E23: 1 | F23: =D23+E23 -> 5601 | G23: Designated Small Fixtures / Decorative Light Strings | H23: Rope / Strip / Ribbon / Tape Lights Products are reported and applied fees in increments of 10 meters. Products of 10 meters or less are applied one recycling fee. Products greater than 10 meters are charged one recycling fee per 10-meter increment (i.e., 38 meters of rope lights would be reported as 4 units and assessed four fees). Members may choose to calculate a fee rate / unit sold to apply at point of sale and then bundle this into increments of 10 meters / $0.15 for reporting purposes. | I23: 3
... A59: 11 | B59: =A59*5-4 -> 51 | C59: =B59*100 -> 5100 | D59: =C59+1000 -> 6100 | E59: 1 | F59: =D59+E59 -> 6101 | G59: Lighting Ballasts / Transformers (not integrated into lamps or fixtures) | H59: Ballasts, all types (i.e., compact fluorescent, electronic, HID, magnetic etc.) | I59: 4

Sheet Old - product_category_id
A1: product_category | B1: product_category_id
A2: Fluorescent tubes measuring less than or equal to 2 ft | B2: 1101
A3: Fluorescent tubes measuring greater than 2 ft and up to or equal to 4 ft | B3: 1601
A4: Fluorescent tubes measuring greater than 4 ft | B4: 2101
A5: Compact Fluorescent Lights (CFL) / Screw-In Induction Lamps | B5: 2601
A6: Light Emitting Diodes (LED) - Bulbs | B6: 3101
A7: Light Emitting Diodes | B7: 3102
A8: Light Emitting Diodes (LED) - Tubes and Other | B8: 3601
A9: High Intensity Discharge (HID), Germicidal, Special Purpose and Other | B9: 4101
A10: Incandescent / Halogen | B10: 4601
A11: Miniature Bulb Package | B11: 5101
A12: Designated Small Fixtures / Decorative Light Strings | B12: 5601
A13: Fixture Category A - Portable Fixtures with a plug, cord, or battery | B13: 5602
... A21: Lighting Ballasts / Transformers (not integrated into lamps or fixtures) | B21: 6101
